### 2024-10-31
#### 问题背景
测试出现预料外的情况
```javascript
await waitFor(() => {
    expect(forgotPasswordPageOtpInput.value).toBe('123456');
    const passwordPageOtpInputError = container.querySelector('#otp-input-error');
    expect(passwordPageOtpInputError).toBeInTheDocument();
});
```
上面的测试执行失败，没有看到error

#### 根本原因
```javascript
async function handleContinue() {
    try {
      await otpHook.funcB(argv, () => {
          funcA();
        });
    } catch (error) {
      if (error.statusCode === 400 && logicA()) {
        setError();
      } else {
        doNothing();
      }
    }
  }
```
正常情况下，funcB调用接口失败，会抛出一个error，statusCode为400，但是funcA同时调用失败抛出异常，该error覆盖了旧error，导致catch走了else分支，出现了预料外的情况

#### 修复方法
修复funcA，因为我们期待他是调用成功的
